Workbook

Sheet Direct Route-3A Tue, Wed & Fri
B3: VOC-CHAMKANI
B4: TRIP SCHEDULES/OPERATION PLAN EFFECTIVE FROM August 1st, 2025 TILL FURTHER ORDERS
B5: DAYS | C5: Tue, Wed & Fri
B6: ROUTE TYPE | C6: Direct Route
B7: ROUTE NAME/ NUMBER | C7: Direct Route-3A
B8: ROUTE DESCRIPTION | C8: Kohat Adda to Dabgari Gardens
B9: OPERATING HOURS | C9: Start Time of Operation: 6:00 AM ; End Time of Operation: 9:30 PM
B10: TYPE OF OPERATION | C10: HEADWAY BASED OPERATIONS as per below headway, displayed on OBU
B11: MAXIMUM SPEED | C11: 50 KM/H (±10 %) subject to local speed restrictions and safety of public as well as passengers
B12: JOURNEY TIME | C12: 20 Minutes; in accordance with Planned Time displayed on OBU for every station
B13: FLEET SIZE REQUIRED | C13: Total 12 Number of Standard-Buses (12-meter)
B14: STOPPAGE/STATION ON OFF-CORRIDOR | C14: EVERY BUS STATION ALONG THE PUBLIC TRANSPORT ROUTE. The bus must stop at bus bay/shelter available within 50 meter distance of Bus Post/ Shelter.
B15: STOPPING BAY ON CORRIDOR | C15: As announced and shown on OBU i.e. 3rd Bay at BRT Station
B16: DWELL TIME | C16: ON-CORRIDOR: MINIMUM 10 SECONDS & MAXIMUM 30 SECONDS SUBJECT TO PASSENGER SAFETY OFF-CORRIDOR: MINIMUM 10 SECONDS & MAXIMUM 45 SECONDS SUBJECT TO PASSENGER SAFETY
B17: Route | C17: FROM | D17: TO | E17: DURATION (Hours) | F17: TRIPS/hr (No.) | G17: Headway (Minutes) | H17: Journey Time (h:m:s) | I17: PATH
B19: Direct Route-3A | C19: =DETAILS!D12 -> 0.25 | D19: =DETAILS!D13 -> 0.26041667 | E19: =D19-C19 -> 0.010416667 | F19: =(E19/G19)+1 -> 2 | G19: =DETAILS!C13 -> 0.010416667 | H19: =TIME(0,20,0) -> 0.013888889 | I19: Dabgari Gardens to Kohat Adda
C20: =DETAILS!D14 -> 0.26736111 | F20: =(E20/G20)+1 -> 1 | G20: =DETAILS!C14 -> 0.0069444444
C21: =DETAILS!D15 -> 0.27083333 | D21: =DETAILS!D45 -> 0.375 | E21: =D21-C21 -> 0.10416667 | F21: =(E21/G21)+1 -> 31 | G21: =DETAILS!C18 -> 0.0034722222
C22: =DETAILS!D46 -> 0.37916667 | D22: =DETAILS!D75 -> 0.5 | E22: =D22-C22 -> 0.12083333 | F22: =(E22/G22)+1 -> 30 | G22: =DETAILS!C50 -> 0.0041666667
C23: =DETAILS!D76 -> 0.50347222 | D23: =DETAILS!D99 -> 0.58333333 | E23: =D23-C23 -> 0.079861111 | F23: =(E23/G23)+1 -> 24 | G23: =DETAILS!C77 -> 0.0034722222
C24: =DETAILS!D100 -> 0.5875 | D24: =DETAILS!D129 -> 0.70833333 | E24: =D24-C24 -> 0.12083333 | F24: =(E24/G24)+1 -> 30 | G24: =DETAILS!C103 -> 0.0041666667
C25: =DETAILS!D130 -> 0.71180556 | D25: =DETAILS!D163 -> 0.82638889 | E25: =D25-C25 -> 0.11458333 | F25: =(E25/G25)+1 -> 34 | G25: =DETAILS!C136 -> 0.0034722222
C26: =DETAILS!D164 -> 0.83055556 | D26: =DETAILS!D170 -> 0.85555556 | E26: =D26-C26 -> 0.025 | F26: =(E26/G26)+1 -> 7 | G26: =DETAILS!C168 -> 0.0041666667
C27: =DETAILS!D171 -> 0.86041667 | D27: =DETAILS!D174 -> 0.875 | E27: =D27-C27 -> 0.014583333 | F27: =(E27/G27)+1 -> 4 | G27: =DETAILS!C173 -> 0.0048611111
C28: Sub-total Forward | E28: =SUM(E19:E25) -> 0.55069444 | F28: =SUM(F19:F27) -> 163 | I28: Kohat Adda to Dabgari Gardens
C29: =DETAILS!K12 -> 0.25 | D29: =DETAILS!K13 -> 0.26041667 | E29: =D29-C29 -> 0.010416667 | F29: =(E29/G29)+1 -> 2 | G29: =DETAILS!J13 -> 0.010416667
C30: =DETAILS!K14 -> 0.26736111 | D30: =DETAILS!K15 -> 0.27430556 | E30: =D30-C30 -> 0.0069444444 | F30: =(E30/G30)+1 -> 2 | G30: =DETAILS!J15 -> 0.0069444444
C31: =DETAILS!K16 -> 0.27777778 | D31: =DETAILS!K45 -> 0.37847222 | E31: =D31-C31 -> 0.10069444 | F31: =(E31/G31)+1 -> 30 | G31: =DETAILS!J29 -> 0.0034722222
C32: =DETAILS!K46 -> 0.38263889 | D32: =DETAILS!K75 -> 0.50347222 | E32: =D32-C32 -> 0.12083333 | F32: =(E32/G32)+1 -> 30 | G32: =DETAILS!J48 -> 0.0041666667
C33: =DETAILS!K76 -> 0.50694444 | D33: =DETAILS!K99 -> 0.58680556 | E33: =D33-C33 -> 0.079861111 | F33: =(E33/G33)+1 -> 24 | G33: =DETAILS!J99 -> 0.0034722222
C34: =DETAILS!K100 -> 0.59097222 | D34: =DETAILS!K129 -> 0.71180556 | E34: =D34-C34 -> 0.12083333 | F34: =(E34/G34)+1 -> 30 | G34: =DETAILS!J63 -> 0.0041666667
C35: =DETAILS!K130 -> 0.71527778 | D35: =DETAILS!K165 -> 0.83680556 | E35: =D35-C35 -> 0.12152778 | F35: =(E35/G35)+1 -> 36 | G35: =DETAILS!J140 -> 0.0034722222
C36: =DETAILS!K166 -> 0.84097222 | D36: =DETAILS!K171 -> 0.86180556 | E36: =D36-C36 -> 0.020833333 | F36: =(E36/G36)+1 -> 6 | G36: =DETAILS!J169 -> 0.0041666667
C37: =DETAILS!K172 -> 0.86666667 | D37: =DETAILS!K178 -> 0.89583333 | E37: =D37-C37 -> 0.029166667 | F37: =(E37/G37)+1 -> 7 | G37: =DETAILS!J176 -> 0.0048611111
C38: Sub-total Backward | E38: =SUM(E29:E36) -> 0.58194444 | F38: =SUM(F29:F37) -> 167
C39: Total Trips | F39: =F38+F28 -> 330
C40: Time/ Location | D40: Direction | F40: TRIPS | G40: Total
C41: Depot | D41: Dabgari Gardens | E41: Morning Dead Trips | F41: 8 | I41: Morning Dead Trips
C42: Depot | D42: kohat Adda | F42: 4
C43: Dabgari Gardens | D43: Depot | E43: Evening Dead Trips | F43: 12 | I43: Evening Dead Trips
...

Sheet DETAILS
B1: Headway B1 F | C1: 0.010416667 | E1: Layover B1 | F1: 0.013888889 | G1: 0.017361111 | I1: Headway B1 B | J1: 0.010416667 | L1: Layover B1 | M1: 0.0125 | N1: 0.0048611111
B2: Headway B2 F | C2: 0.0069444444 | E2: Layover B2 | F2: 0.011805556 | G2: 0.015277778 | I2: Headway B2 B | J2: 0.0069444444 | L2: Layover B2 | M2: 0.011805556 | N2: 24
B3: Headway B3 F | C3: 0.0041666667 | D3: 0.0041666667 | E3: Layover B3 | F3: 0.010416667 | I3: Headway B3 B | J3: 0.0048611111 | L3: Layover B3 | M3: 0.010416667
B4: Headway B4 F | C4: 0.0083333333 | D4: 0.0048611111 | E4: Layover B4 | F4: 0.0097222222 | G4: 0.0013888889 | I4: Headway B4 B | J4: 0.0083333333 | L4: Layover B4 | M4: 0.0097222222 | N4: 0.016666667
B5: Headway B3 F | C5: 0.0034722222 | E5: Layover B5 | F5: 0.0069444444 | I5: Start of Operation | J5: 0.25 | L5: Layover B5 | M5: 0.0083333333 | N5: 0.0090277778
E6: Layover B6 | F6: 0.0076388889 | I6: Travel Time | J6: 0.013888889 | L6: Layover B6 | M6: 0.0076388889
B7: Start of Operation | C7: 0.25 | E7: Layover B7 | F7: 0.010416667 | J7: 0.0048611111 | L7: Layover B7 | M7: 0.010416667
B8: Travel Time | C8: 0.013888889 | E8: Layover B8 | F8: 0.0048611111 | G8: 0.0055555556 | L8: Layover B8 | M8: 0.0055555556
M9: 0.0034722222
A10: FORWARD DIRECTION (Dabgari Gardens to Kohat Adda ) | I10: BACKWARD DIRECTION ( Kohat Adda to Dabgari Gardens )
A11: Trips NO | B11: Bus No | C11: Headway | D11: Trip Start Time at Dabgari Gardens | E11: Trip End Time at Kohat Adda | F11: Layover Time at Kohat Adda | G11: Readiness for BWD | I11: Bus No | J11: Headway | K11: Trip Start Time Kohat Adda | L11: Trip End Time Dabgari Gardens | M11: Layover Time at Dabgari Gardens | N11: Readiness for FWD
A12: 1 | B12: 1 | D12: =C7 -> 0.25 | E12: =D12+$C$8 -> 0.26388889 | F12: 0.013888889 | G12: =E12+F12 -> 0.27777778 | I12: 9 | K12: =J5 -> 0.25 | L12: =K12+$J$6 -> 0.26388889 | M12: Reserve at Dabgari &move back to depot @ 21:00 pm
A13: 2 | B13: 2 | C13: =C$1 -> 0.010416667 | D13: =C13+D12 -> 0.26041667 | E13: =D13+$C$8 -> 0.27430556 | F13: 0.0069444444 | G13: =E13+F13 -> 0.28125 | I13: 10 | J13: =C13 -> 0.010416667 | K13: =K12+J13 -> 0.26041667 | L13: =K13+$J$6 -> 0.27430556 | M13: Reserve at Dabgari & induct back @ 12:05 pm
A14: 3 | B14: 3 | C14: 0.0069444444 | D14: =D13+C14 -> 0.26736111 | E14: =D14+$C$8 -> 0.28125 | F14: 0.0034722222 | G14: =E14+F14 -> 0.28472222 | I14: 11 | J14: =C14 -> 0.0069444444 | K14: =K13+J14 -> 0.26736111 | L14: =K14+$J$6 -> 0.28125 | M14: 0.0069444444 | N14: =L14+M14 -> 0.28819444
A15: 4 | B15: 4 | C15: 0.0034722222 | D15: =D14+C15 -> 0.27083333 | E15: =D15+$C$8 -> 0.28472222 | F15: 0.0034722222 | G15: =E15+F15 -> 0.28819444 | I15: 12 | J15: 0.0069444444 | K15: =K14+J15 -> 0.27430556 | L15: =K15+$J$6 -> 0.28819444 | M15: 0.0034722222 | N15: =L15+M15 -> 0.29166667
A16: 5 | B16: 5 | C16: =C$5 -> 0.0034722222 | D16: =D15+C16 -> 0.27430556 | E16: =D16+$C$8 -> 0.28819444 | F16: 0.0034722222 | G16: =E16+F16 -> 0.29166667 | I16: =B12 -> 1 | J16: =C16 -> 0.0034722222 | K16: =K15+J16 -> 0.27777778 | L16: =K16+$J$6 -> 0.29166667 | M16: 0.0034722222 | N16: =L16+M16 -> 0.29513889
A17: 6 | B17: 6 | C17: =C$5 -> 0.0034722222 | D17: =D16+C17 -> 0.27777778 | E17: =D17+$C$8 -> 0.29166667 | F17: 0.0034722222 | G17: =E17+F17 -> 0.29513889 | I17: =B13 -> 2 | J17: =C17 -> 0.0034722222 | K17: =K16+J17 -> 0.28125 | L17: =K17+$J$6 -> 0.29513889 | M17: 0.0034722222 | N17: =L17+M17 -> 0.29861111
A18: 7 | B18: 7 | C18: =C$5 -> 0.0034722222 | D18: =D17+C18 -> 0.28125 | E18: =D18+$C$8 -> 0.29513889 | F18: 0.0034722222 | G18: =E18+F18 -> 0.29861111 | I18: =B14 -> 3 | J18: =C18 -> 0.0034722222 | K18: =K17+J18 -> 0.28472222 | L18: =K18+$J$6 -> 0.29861111 | M18: 0.0034722222 | N18: =L18+M18 -> 0.30208333
A19: 8 | B19: 8 | C19: =C$5 -> 0.0034722222 | D19: =D18+C19 -> 0.28472222 | E19: =D19+$C$8 -> 0.29861111 | F19: 0.0034722222 | G19: =E19+F19 -> 0.30208333 | I19: =B15 -> 4 | J19: =C19 -> 0.0034722222 | K19: =K18+J19 -> 0.28819444 | L19: =K19+$J$6 -> 0.30208333 | M19: 0.0034722222 | N19: =L19+M19 -> 0.30555556
A20: 9 | B20: =I14 -> 11 | C20: =C$5 -> 0.0034722222 | D20: =D19+C20 -> 0.28819444 | E20: =D20+$C$8 -> 0.30208333 | F20: 0.0034722222 | G20: =E20+F20 -> 0.30555556 | I20: =B16 -> 5 | J20: =C20 -> 0.0034722222 | K20: =K19+J20 -> 0.29166667 | L20: =K20+$J$6 -> 0.30555556 | M20: 0.0034722222 | N20: =L20+M20 -> 0.30902778
A21: 10 | B21: =I15 -> 12 | C21: =C$5 -> 0.0034722222 | D21: =D20+C21 -> 0.29166667 | E21: =D21+$C$8 -> 0.30555556 | F21: 0.0034722222 | G21: =E21+F21 -> 0.30902778 | I21: =B17 -> 6 | J21: =C21 -> 0.0034722222 | K21: =K20+J21 -> 0.29513889 | L21: =K21+$J$6 -> 0.30902778 | M21: 0.0034722222 | N21: =L21+M21 -> 0.3125
A22: 11 | B22: =I16 -> 1 | C22: =C$5 -> 0.0034722222 | D22: =D21+C22 -> 0.29513889 | E22: =D22+$C$8 -> 0.30902778 | F22: 0.0034722222 | G22: =E22+F22 -> 0.3125 | I22: =B18 -> 7 | J22: =C22 -> 0.0034722222 | K22: =K21+J22 -> 0.29861111 | L22: =K22+$J$6 -> 0.3125 | M22: 0.0034722222 | N22: =L22+M22 -> 0.31597222
A23: 12 | B23: =I17 -> 2 | C23: =C$5 -> 0.0034722222 | D23: =D22+C23 -> 0.29861111 | E23: =D23+$C$8 -> 0.3125 | F23: 0.0034722222 | G23: =E23+F23 -> 0.31597222 | I23: =B19 -> 8 | J23: =C23 -> 0.0034722222 | K23: =K22+J23 -> 0.30208333 | L23: =K23+$J$6 -> 0.31597222 | M23: 0.0034722222 | N23: =L23+M23 -> 0.31944444
A24: 13 | B24: =I18 -> 3 | C24: =C$5 -> 0.0034722222 | D24: =D23+C24 -> 0.30208333 | E24: =D24+$C$8 -> 0.31597222 | F24: 0.0034722222 | G24: =E24+F24 -> 0.31944444 | I24: =B20 -> 11 | J24: =C24 -> 0.0034722222 | K24: =K23+J24 -> 0.30555556 | L24: =K24+$J$6 -> 0.31944444 | M24: 0.0034722222 | N24: =L24+M24 -> 0.32291667
A25: 14 | B25: =I19 -> 4 | C25: =C$5 -> 0.0034722222 | D25: =D24+C25 -> 0.30555556 | E25: =D25+$C$8 -> 0.31944444 | F25: 0.0034722222 | G25: =E25+F25 -> 0.32291667 | I25: =B21 -> 12 | J25: =C25 -> 0.0034722222 | K25: =K24+J25 -> 0.30902778 | L25: =K25+$J$6 -> 0.32291667 | M25: 0.0034722222 | N25: =L25+M25 -> 0.32638889
A26: 15 | B26: =I20 -> 5 | C26: =C$5 -> 0.0034722222 | D26: =D25+C26 -> 0.30902778 | E26: =D26+$C$8 -> 0.32291667 | F26: 0.0034722222 | G26: =E26+F26 -> 0.32638889 | I26: =B22 -> 1 | J26: =C26 -> 0.0034722222 | K26: =K25+J26 -> 0.3125 | L26: =K26+$J$6 -> 0.32638889 | M26: 0.0034722222 | N26: =L26+M26 -> 0.32986111
A27: 16 | B27: =I21 -> 6 | C27: =C$5 -> 0.0034722222 | D27: =D26+C27 -> 0.3125 | E27: =D27+$C$8 -> 0.32638889 | F27: 0.0034722222 | G27: =E27+F27 -> 0.32986111 | I27: =B23 -> 2 | J27: =C27 -> 0.0034722222 | K27: =K26+J27 -> 0.31597222 | L27: =K27+$J$6 -> 0.32986111 | M27: 0.0034722222 | N27: =L27+M27 -> 0.33333333
A28: 17 | B28: =I22 -> 7 | C28: =C$5 -> 0.0034722222 | D28: =D27+C28 -> 0.31597222 | E28: =D28+$C$8 -> 0.32986111 | F28: 0.0034722222 | G28: =E28+F28 -> 0.33333333 | I28: =B24 -> 3 | J28: =C28 -> 0.0034722222 | K28: =K27+J28 -> 0.31944444 | L28: =K28+$J$6 -> 0.33333333 | M28: 0.0034722222 | N28: =L28+M28 -> 0.33680556
A29: 18 | B29: =I23 -> 8 | C29: =C$5 -> 0.0034722222 | D29: =D28+C29 -> 0.31944444 | E29: =D29+$C$8 -> 0.33333333 | F29: 0.0034722222 | G29: =E29+F29 -> 0.33680556 | I29: =B25 -> 4 | J29: =C29 -> 0.0034722222 | K29: =K28+J29 -> 0.32291667 | L29: =K29+$J$6 -> 0.33680556 | M29: 0.0034722222 | N29: =L29+M29 -> 0.34027778
A30: 19 | B30: =I24 -> 11 | C30: =C$5 -> 0.0034722222 | D30: =D29+C30 -> 0.32291667 | E30: =D30+$C$8 -> 0.33680556 | F30: 0.0034722222 | G30: =E30+F30 -> 0.34027778 | I30: =B26 -> 5 | J30: =C30 -> 0.0034722222 | K30: =K29+J30 -> 0.32638889 | L30: =K30+$J$6 -> 0.34027778 | M30: 0.0034722222 | N30: =L30+M30 -> 0.34375
A31: 20 | B31: =I25 -> 12 | C31: =C$5 -> 0.0034722222 | D31: =D30+C31 -> 0.32638889 | E31: =D31+$C$8 -> 0.34027778 | F31: 0.0034722222 | G31: =E31+F31 -> 0.34375 | I31: =B27 -> 6 | J31: =C31 -> 0.0034722222 | K31: =K30+J31 -> 0.32986111 | L31: =K31+$J$6 -> 0.34375 | M31: 0.0034722222 | N31: =L31+M31 -> 0.34722222
... A43: 32 | B43: =I37 -> 2 | C43: =C$5 -> 0.0034722222 | D43: =D42+C43 -> 0.36805556 | E43: =D43+$C$8 -> 0.38194444 | F43: 0.0048611111 | G43: =E43+F43 -> 0.38680556 | I43: =B39 -> 8 | J43: =C43 -> 0.0034722222 | K43: =K42+J43 -> 0.37152778 | L43: =K43+$J$6 -> 0.38541667 | M43: 0.00625 | N43: =L43+M43 -> 0.39166667
A44: 33 | B44: =I38 -> 3 | C44: =C$5 -> 0.0034722222 | D44: =D43+C44 -> 0.37152778 | E44: =D44+$C$8 -> 0.38541667 | F44: 0.0055555556 | G44: =E44+F44 -> 0.39097222 | I44: =B40 -> 11 | J44: =C44 -> 0.0034722222 | K44: =K43+J44 -> 0.375 | L44: =K44+$J$6 -> 0.38888889 | M44: Reserve at Dabgari & induct back @ 12:35 pm
A45: 34 | B45: =I39 -> 4 | C45: =C$5 -> 0.0034722222 | D45: =D44+C45 -> 0.375 | E45: =D45+$C$8 -> 0.38888889 | F45: 0.00625 | G45: =E45+F45 -> 0.39513889 | I45: =B41 -> 12 | J45: =C45 -> 0.0034722222 | K45: =K44+J45 -> 0.37847222 | L45: =K45+$J$6 -> 0.39236111 | M45: 0.0034722222 | N45: =L45+M45 -> 0.39583333
A46: 35 | B46: =I40 -> 5 | C46: =D$3 -> 0.0041666667 | D46: =D45+C46 -> 0.37916667 | E46: =D46+$C$8 -> 0.39305556 | F46: 0.00625 | G46: =E46+F46 -> 0.39930556 | I46: =B42 -> 1 | J46: =C46 -> 0.0041666667 | K46: =K45+J46 -> 0.38263889 | L46: =K46+$J$6 -> 0.39652778 | M46: 0.0034722222 | N46: =L46+M46 -> 0.4
A47: 36 | B47: =I41 -> 6 | C47: =D$3 -> 0.0041666667 | D47: =D46+C47 -> 0.38333333 | E47: =D47+$C$8 -> 0.39722222 | F47: 0.00625 | G47: =E47+F47 -> 0.40347222 | I47: =B43 -> 2 | J47: =C47 -> 0.0041666667 | K47: =K46+J47 -> 0.38680556 | L47: =K47+$J$6 -> 0.40069444 | M47: 0.0034722222 | N47: =L47+M47 -> 0.40416667
A48: 37 | B48: =I42 -> 7 | C48: =D$3 -> 0.0041666667 | D48: =D47+C48 -> 0.3875 | E48: =D48+$C$8 -> 0.40138889 | F48: 0.00625 | G48: =E48+F48 -> 0.40763889 | I48: =B44 -> 3 | J48: =C48 -> 0.0041666667 | K48: =K47+J48 -> 0.39097222 | L48: =K48+$J$6 -> 0.40486111 | M48: 0.0034722222 | N48: =L48+M48 -> 0.40833333
A49: 38 | B49: =I43 -> 8 | C49: =D$3 -> 0.0041666667 | D49: =D48+C49 -> 0.39166667 | E49: =D49+$C$8 -> 0.40555556 | F49: 0.00625 | G49: =E49+F49 -> 0.41180556 | I49: =B45 -> 4 | J49: =C49 -> 0.0041666667 | K49: =K48+J49 -> 0.39513889 | L49: =K49+$J$6 -> 0.40902778 | M49: 0.0034722222 | N49: =L49+M49 -> 0.4125
A50: 39 | B50: =I45 -> 12 | C50: =D$3 -> 0.0041666667 | D50: =D49+C50 -> 0.39583333 | E50: =D50+$C$8 -> 0.40972222 | F50: 0.00625 | G50: =E50+F50 -> 0.41597222 | I50: =B46 -> 5 | J50: =C50 -> 0.0041666667 | K50: =K49+J50 -> 0.39930556 | L50: =K50+$J$6 -> 0.41319444 | M50: 0.0034722222 | N50: =L50+M50 -> 0.41666667
A51: 40 | B51: =I46 -> 1 | C51: =D$3 -> 0.0041666667 | D51: =D50+C51 -> 0.4 | E51: =D51+$C$8 -> 0.41388889 | F51: 0.00625 | G51: =E51+F51 -> 0.42013889 | I51: =B47 -> 6 | J51: =C51 -> 0.0041666667 | K51: =K50+J51 -> 0.40347222 | L51: =K51+$J$6 -> 0.41736111 | M51: 0.0034722222 | N51: =L51+M51 -> 0.42083333
...

Sheet Sheet1
E3: 19.673 | F3: 148 | G3: =F3*E3 -> 2911.604
E4: 4.74 | F4: 288 | G4: =F4*E4 -> 1365.12
G5: =G3-G4 -> 1546.484
